Workbook

Sheet Productos
A1: N° | B1: Casa | C1: Producto | D1: Destacado | E1: Familia olfativa | F1: Género | G1: Notas olfativas | H1: Presentación | I1: Tipo | J1: Volumen (ml) | K1: Año de lanzamiento | L1: Duración estimada | M1: Precio (ARS) | N1: Precio mostrado | O1: Consulta | P1: Foto (archivo)
A2: 1 | B2: AFNAN | C2: 9 AM DIVE | D2: Sí | E2: Cítrico / Fresco | F2: Unisex | G2: Limón, Menta, Grosella Negra, Manzana, Cedro | H2: EDP 100ML | I2: EDP | J2: 100 | K2: 2022 | L2: Moderada (aprox. 4–8h, varía según piel) | M2: 75508 | N2: $75.508 | O2: Escribir por WhatsApp | P2: imagenes/9-am-dive-afnan.webp
A3: 2 | B3: AFNAN | C3: 9 AM ROSA FEM | D3: No | E3: Floral | F3: Femenino | G3: Rosa Matutina, Cítricos, Peonía, Almizcle Blanco | H3: EDP 100ML | I3: EDP | J3: 100 | K3: 2022 | L3: Moderada (4–6h) | M3: 87411 | N3: $87.411 | O3: Escribir por WhatsApp | P3: imagenes/9-am-rosa-fem-afnan.webp
A4: 3 | B4: AFNAN | C4: 9 PM | D4: No | E4: Gourmand | F4: Unisex | G4: Manzana, Canela, Lavanda, Azahar, Vainilla | H4: EDP 100ML | I4: EDP | J4: 100 | K4: 2020 | L4: Muy alta (8–12h+) | M4: 70000 | N4: $70.000 | O4: Escribir por WhatsApp | P4: imagenes/9-pm-afnan.webp
A5: 4 | B5: AFNAN | C5: 9 PM ELIXIR | D5: No | E5: Gourmand | F5: Unisex | G5: Manzana Acaramelada, Especias Oscuras, Tonka | H5: ELIXIR 100ML | I5: ELIXIR | J5: 100 | K5: 2025 | L5: Muy alta (8–12h+) | M5: 107277 | N5: $107.277 | O5: Escribir por WhatsApp | P5: imagenes/9-pm-elixir-afnan.webp
A6: 5 | B6: AFNAN | C6: 9 PM NIGHT OUT | D6: No | E6: Ámbar Oriental | F6: Unisex | G6: Cítricos Chispeantes, Especias, Cuero, Ámbar | H6: EDP 100ML | I6: EDP | J6: 100 | K6: 2026 | L6: Alta (6–8h) | M6: 140763 | N6: $140.763 | O6: Escribir por WhatsApp | P6: imagenes/9-pm-night-out-afnan.webp
A7: 6 | B7: AFNAN | C7: 9 PM REBEL | D7: No | E7: Cítrico / Fresco | F7: Unisex | G7: Piña, Mandarina, Menta, Maderas Nobles, Ámbar | H7: EDP 100ML | I7: EDP | J7: 100 | K7: 2024 | L7: Muy alta (8–12h+) | M7: 106491 | N7: $106.491 | O7: Escribir por WhatsApp | P7: imagenes/9-pm-rebel-afnan.webp
A8: 7 | B8: AFNAN | C8: THURATI BLUE | D8: No | E8: Amaderado / Oud | F8: Unisex | G8: Toronja, Ámbar, Maderas, Almizcle | H8: EDP 100ML | I8: EDP | J8: 100 | K8: 2021 | L8: Moderada-Alta (5–7h) | M8: 79874 | N8: $79.874 | O8: Escribir por WhatsApp | P8: imagenes/thurati-blue-afnan.webp
A9: 8 | B9: AFNAN | C9: TURATHI ELECTRIC | D9: No | E9: Cítrico / Fresco | F9: Unisex | G9: Toronja, Menta, Pimienta Rosa, Cedro | H9: EDP 100ML | I9: EDP | J9: 100 | K9: 2025 | L9: Moderada (4–6h) | N9: Consultar | O9: Escribir por WhatsApp
A10: 9 | B10: AL HARAMAIN | C10: AQUA DUBAI | D10: Sí | E10: Cítrico / Fresco | F10: Unisex | G10: Bergamota, Mandarina, Acordes Marinos | H10: EDP 100ML | I10: EDP | J10: 100 | K10: 2024 | L10: Alta (6–8h) | M10: 122112 | N10: $122.112 | O10: Escribir por WhatsApp | P10: imagenes/aqua-dubai-al-haramain.webp
A11: 10 | B11: AL HARAMAIN | C11: DUBAI NIGHT | D11: No | E11: Ámbar Oriental | F11: Unisex | G11: Especias Oscuras, Ámbar, Vainilla | H11: EDP 100ML | I11: EDP | J11: 100 | K11: Consultar | L11: Consultar | M11: 125690 | N11: $125.690 | O11: Escribir por WhatsApp | P11: imagenes/dubai-night-al-haramain.webp
A12: 11 | B12: AL HARAMAIN | C12: GOLD EDITION | D12: No | E12: Gourmand | F12: Unisex | G12: Cítricos, Piña, Ámbar, Vainilla | H12: EDP 120ML | I12: EDP | J12: 120 | K12: Consultar | L12: Consultar | M12: 131103 | N12: $131.103 | O12: Escribir por WhatsApp | P12: imagenes/gold-edition-al-haramain.webp
A13: 12 | B13: AL WATANIAH | C13: SABAH AL WARD | D13: Sí | E13: Oriental Amaderado | F13: Unisex | G13: Notas exactas no confirmadas en fuentes públicas; perfil floral (línea Sabah Al Ward) | H13: EDP 100ML | I13: EDP | J13: 100 | K13: Consultar | L13: Consultar | M13: 45696 | N13: $45.696 | O13: Escribir por WhatsApp | P13: imagenes/sabah-al-ward-al-wataniah.webp
A14: 13 | B14: ARMAF | C14: CLUB DE NUIT BLING | D14: Sí | E14: Gourmand | F14: Unisex | G14: Cítricos, Flower Prism, Stardust / Velvet Woods, Vainilla | H14: EDP | I14: EDP | K14: 2025 | L14: Moderada-Alta (5–7h) | M14: 98476 | N14: $98.476 | O14: Escribir por WhatsApp | P14: imagenes/club-de-nuit-bling-armaf.webp
A15: 14 | B15: ARMAF | C15: CLUB DE NUIT BLUE ICONIC | D15: No | E15: Amaderado / Oud | F15: Masculino | G15: Toronja, Limón, Menta, Pimienta Rosa, Cilantro / Jengibre, Melón, Jazmín, Nuez Moscada / Amaderadas, Incienso, Sándalo, Ámbar, Cedro, Pachulí, Ládano | H15: EDP 105ML | I15: EDP | J15: 105 | K15: 2022 | L15: Alta (aprox. 6–9h) | M15: 97809 | N15: $97.809 | O15: Escribir por WhatsApp | P15: imagenes/club-de-nuit-blue-iconic-armaf.webp
A16: 15 | B16: ARMAF | C16: CLUB DE NUIT INTENSE MAN | D16: No | E16: Floral | F16: Masculino | G16: Limón, Piña, Bergamota, Grosella Negra, Manzana / Abedul, Jazmín, Rosa / Almizcle, Ámbar Gris, Pachulí, Vainilla | H16: EDP | I16: EDP | K16: 2015 | L16: Muy alta (8–12h+) | M16: 84429 | N16: $84.429 | O16: Escribir por WhatsApp | P16: imagenes/club-de-nuit-intense-man-armaf.webp
A17: 16 | B17: ARMAF | C17: CLUB DE NUIT MALEKA | D17: No | E17: Ámbar Oriental | F17: Unisex | G17: Flores Blancas Exóticas, Cítricos Dorados, Ámbar | H17: EDP 100ML | I17: EDP | J17: 100 | K17: 2025 | L17: Alta (6–8h) | M17: 94017 | N17: $94.017 | O17: Escribir por WhatsApp | P17: imagenes/club-de-nuit-maleka-armaf.webp
A18: 17 | B18: ARMAF | C18: CLUB DE NUIT PRECIEUX | D18: No | E18: Amaderado / Oud | F18: Masculino | G18: Piña, Bergamota, Dulce de Pimienta, Maderas Lujosas | H18: EXTRAIT PARFUM 55ML | I18: EXTRAIT PARFUM | J18: 55 | K18: 2024 | L18: Alta (6–8h) | M18: 139785 | N18: $139.785 | O18: Escribir por WhatsApp | P18: imagenes/club-de-nuit-precieux-armaf.webp
A19: 18 | B19: ARMAF | C19: CLUB DE NUIT SILLAGE | D19: No | E19: Floral | F19: Unisex | G19: Bergamota, Grosella Negra, Violeta, Ambroxan | H19: EDP 105ML | I19: EDP | J19: 105 | K19: 2020 | L19: Alta (6–8h) | M19: 86050 | N19: $86.050 | O19: Escribir por WhatsApp | P19: imagenes/club-de-nuit-sillage-armaf.webp
A20: 19 | B20: ARMAF | C20: CLUB DE NUIT UNTOLD | D20: No | E20: Amaderado / Oud | F20: Unisex | G20: Azafrán, Jazmín, Amberwood, Resina de Abeto, Cedro | H20: EDP 105ML | I20: EDP | J20: 105 | K20: 2022 | L20: Moderada (4–6h) | M20: 96354 | N20: $96.354 | O20: Escribir por WhatsApp | P20: imagenes/club-de-nuit-untold-armaf.webp
A21: 20 | B21: ARMAF | C21: CLUB DE NUIT URBAN MAN ELIXIR | D21: No | E21: Amaderado / Oud | F21: Masculino | G21: Bergamota, Pimienta, Lavanda, Ambroxan, Pachulí | H21: ELIXIR 105ML | I21: ELIXIR | J21: 105 | K21: 2022 | L21: Muy alta (8–12h+) | M21: 102054 | N21: $102.054 | O21: Escribir por WhatsApp | P21: imagenes/club-de-nuit-urban-man-elixir-armaf.webp
A22: 21 | B22: ARMAF | C22: CLUB DE NUIT WOMAN | D22: No | E22: Floral | F22: Femenino | G22: Naranja, Bergamota, Rosa, Jazmín, Pachulí, Vainilla | H22: EDP 105ML | I22: EDP | J22: 105 | K22: Consultar | L22: Moderada-Alta (5–7h) | M22: 88604 | N22: $88.604 | O22: Escribir por WhatsApp | P22: imagenes/club-de-nuit-woman-armaf.webp
A23: 22 | B23: ARMAF | C23: MANDARIN SKY | D23: No | E23: Gourmand | F23: Unisex | G23: Mandarina, Caramelo, Tonka, Salvia, Cítricos | H23: EDP 100ML | I23: EDP | J23: 100 | K23: 2023 | L23: Moderada-Alta (5–7h) | M23: 69738 | N23: $69.738 | O23: Escribir por WhatsApp | P23: imagenes/mandarin-sky-armaf.webp
A24: 23 | B24: ARMAF | C24: MANDARIN SKY ELIXIR | D24: No | E24: Gourmand | F24: Unisex | G24: Mandarina Dulce, Caramelo Concentrado, Ámbar | H24: ELIXIR 100ML | I24: ELIXIR | J24: 100 | K24: 2025 | L24: Alta (6–8h) | M24: 99406 | N24: $99.406 | O24: Escribir por WhatsApp | P24: imagenes/mandarin-sky-elixir-armaf.webp
A25: 24 | B25: ARMAF | C25: ODYSSEY AQUA | D25: No | E25: Cítrico / Fresco | F25: Unisex | G25: Toronja, Menta, Violeta, Pachulí, Ámbar | H25: EDP 100ML | I25: EDP | J25: 100 | K25: 2023 | L25: Alta (6–8h) | M25: 79516 | N25: $79.516 | O25: Escribir por WhatsApp | P25: imagenes/odyssey-aqua-armaf.webp
A26: 25 | B26: ARMAF | C26: ODYSSEY BAHAMAS | D26: No | E26: Acuático / Marino | F26: Unisex | G26: Coco, Brisa Marina, Cítricos Tropicales | H26: EDP 100ML | I26: EDP | J26: 100 | K26: 2025 | L26: Moderada (4–6h) | M26: 98262 | N26: $98.262 | O26: Escribir por WhatsApp | P26: imagenes/odyssey-bahamas-armaf.webp
A27: 26 | B27: ARMAF | C27: ODYSSEY CANDE | D27: No | E27: Gourmand | F27: Unisex | G27: Caramelo, Cacao, Especias Dulces, Vainilla | H27: EDP 100ML | I27: EDP | J27: 100 | K27: 2024 | L27: Moderada-Alta (5–7h) | M27: 56120 | N27: $56.120 | O27: Escribir por WhatsApp | P27: imagenes/odyssey-cande-armaf.webp
A28: 27 | B28: ARMAF | C28: ODYSSEY GO MANGO | D28: No | E28: Frutal | F28: Unisex | G28: Mango Maduro, Maracuyá, Cítricos, Ámbar | H28: EDP 100ML | I28: EDP | J28: 100 | K28: 2025 | L28: Moderada (4–6h) | M28: 94304 | N28: $94.304 | O28: Escribir por WhatsApp | P28: imagenes/odyssey-go-mango-armaf.webp
A29: 28 | B29: ARMAF | C29: ODYSSEY HOMME BLACK | D29: No | E29: Gourmand | F29: Masculino | G29: Vainilla, Iris, Ámbar, Cuero, Maderas Oscuras | H29: EDP 100ML | I29: EDP | J29: 100 | K29: Consultar | L29: Moderada-Alta (5–7h) | M29: 58552 | N29: $58.552 | O29: Escribir por WhatsApp | P29: imagenes/odyssey-homme-black-armaf.webp
A30: 29 | B30: ARMAF | C30: ODYSSEY HOMME WHITE | D30: No | E30: Amaderado / Oud | F30: Masculino | G30: Yuzu, Pimienta, Acordes Marinos, Maderas | H30: EDP 100ML | I30: EDP | J30: 100 | K30: Consultar | L30: Moderada (4–6h) | M30: 77370 | N30: $77.370 | O30: Escribir por WhatsApp | P30: imagenes/odyssey-homme-white-armaf.webp
A31: 30 | B31: ARMAF | C31: ODYSSEY MEGA | D31: No | E31: Amaderado / Oud | F31: Unisex | G31: Bergamota, Jengibre, Enebro, Salvia, Vetiver | H31: EDP 100ML | I31: EDP | J31: 100 | K31: 2023 | L31: Moderada (4–6h) | M31: 58958 | N31: $58.958 | O31: Escribir por WhatsApp | P31: imagenes/odyssey-mega-armaf.webp
A32: 31 | B32: ASDAAF | C32: AMEERAT AL ARAB | D32: Sí | E32: Floral | F32: Femenino | G32: Uva, Nardo, Jazmín, Almizcle, Madera de Cedro | H32: EDP 100ML | I32: EDP | J32: 100 | K32: 2022 | L32: Buena (aprox. 6–8h) | M32: 47938 | N32: $47.938 | O32: Escribir por WhatsApp | P32: imagenes/ameerat-al-arab-asdaaf.webp
A33: 32 | B33: ASDAAF | C33: AMEERAT AL ARAB PRIVE ROSE | D33: No | E33: Gourmand | F33: Femenino | G33: Notas exactas no confirmadas; misma familia que Ameerat Al Arab Prive (rosa, fresa, vainilla) | H33: EDP | I33: EDP | K33: 2023 | L33: Muy alta (8–12h+) | M33: 52995 | N33: $52.995 | O33: Escribir por WhatsApp | P33: imagenes/ameerat-al-arab-prive-rose-asdaaf.webp
A34: 33 | B34: BHARARA | C34: BHARARA KING 100ML | D34: Sí | E34: Frutal | F34: Masculino | G34: Naranja, Bergamota, Limón / Frutas Tutti-Frutti / Almizcle Blanco, Ámbar, Vainilla | H34: EDP 100ML | I34: EDP | J34: 100 | K34: 2021 | L34: Muy alta (8–12h+) | M34: 142695 | N34: $142.695 | O34: Escribir por WhatsApp | P34: imagenes/bharara-king-100ml-bharara.webp
A35: 34 | B35: BHARARA | C35: BHARARA KING 150ML | D35: No | E35: Frutal | F35: Masculino | G35: Naranja, Bergamota, Limón / Frutas Tutti-Frutti / Almizcle Blanco, Ámbar, Vainilla | H35: EDP 150ML | I35: EDP | J35: 150 | K35: 2021 | L35: Muy alta (8–12h+) | M35: 180258 | N35: $180.258 | O35: Escribir por WhatsApp | P35: imagenes/bharara-king-150ml-bharara.webp
A36: 35 | B36: EMPER | C36: STALLION 53 | D36: Sí | E36: Amaderado / Oud | F36: Masculino | G36: Cardamomo, Violeta / Iris, Ámbar / Sándalo, Cuero, Cedro de Virginia, Papiro | H36: EDP | I36: EDP | K36: 2024 | L36: Alta (aprox. 8–10h) | M36: 52208 | N36: $52.208 | O36: Escribir por WhatsApp | P36: imagenes/stallion-53-emper.webp
A37: 36 | B37: EMPER | C37: UOMO INTENSE | D37: No | E37: Amaderado / Oud | F37: Masculino | G37: Hoja de Violeta, Pomelo, Vainilla / Palisandro, Notas Marinas, Lavanda, Violeta / Ámbar Gris, Vetiver, Amberwood | H37: EDP | I37: EDP | K37: Consultar | L37: Consultar | M37: 59577 | N37: $59.577 | O37: Escribir por WhatsApp | P37: imagenes/uomo-intense-emper.webp
A38: 37 | B38: FRAGRANCE WORLD | C38: TIRAMISU CARAMEL | D38: Sí | E38: Gourmand | F38: Unisex | G38: Café, Cacao, Caramelo Salado, Bizcocho, Vainilla | H38: EDP 100ML | I38: EDP | J38: 100 | K38: Consultar | L38: Consultar | N38: Consultar | O38: Escribir por WhatsApp
A39: 38 | B39: FRENCH AVENUE | C39: AETHER FRENCH AVE | D39: Sí | E39: Amaderado / Oud | F39: Unisex | G39: Manzana Verde, Bergamota, Cedro, Musgo, Guayaba | H39: EDP 100ML | I39: EDP | J39: 100 | K39: 2024 | L39: Moderada (aprox. 3–6h, varía) | M39: 62010 | N39: $62.010 | O39: Escribir por WhatsApp
A40: 39 | B40: FRENCH AVENUE | C40: LIQUID BRUN | D40: No | E40: Ámbar Oriental | F40: Unisex | G40: Canela, Cardamomo, Bourbon, Praliné, Maderas | H40: EDP 100ML | I40: EDP | J40: 100 | K40: 2024 | L40: Alta (6–8h) | M40: 106443 | N40: $106.443 | O40: Escribir por WhatsApp | P40: imagenes/liquid-brun-french-avenue.webp
...

Sheet Casas
A1: Resumen por casa
A3: Casa | B3: Descripción | C3: Cantidad de fragancias | D3: Con precio publicado | E3: Precio mínimo (ARS) | F3: Precio máximo (ARS) | G3: Precio promedio (ARS)
A4: AFNAN | B4: Modernidad árabe con acentos nocturnos: una firma audaz que no pide permiso. | C4: =COUNTIF(Productos!$B$2:$B$148,A4) -> 8 | D4: =COUNTIFS(Productos!$B$2:$B$148,A4,Productos!$M$2:$M$148,"<>") -> 7 | E4: =IF(D4=0,"Consultar",_xlfn.MINIFS(Productos!$M$2:$M$148,Productos!$B$2:$B$148,A4)) -> 70000 | F4: =IF(D4=0,"Consultar",_xlfn.MAXIFS(Productos!$M$2:$M$148,Productos!$B$2:$B$148,A4)) -> 140763 | G4: =IF(D4=0,"Consultar",AVERAGEIFS(Productos!$M$2:$M$148,Productos!$B$2:$B$148,A4)) -> 95332
A5: AL HARAMAIN | B5: Perfumería saudí de tradición centenaria, maestra del oud denso y el ámbar oriental. | C5: =COUNTIF(Productos!$B$2:$B$148,A5) -> 3 | D5: =COUNTIFS(Productos!$B$2:$B$148,A5,Productos!$M$2:$M$148,"<>") -> 3 | E5: =IF(D5=0,"Consultar",_xlfn.MINIFS(Productos!$M$2:$M$148,Productos!$B$2:$B$148,A5)) -> 122112 | F5: =IF(D5=0,"Consultar",_xlfn.MAXIFS(Productos!$M$2:$M$148,Productos!$B$2:$B$148,A5)) -> 131103 | G5: =IF(D5=0,"Consultar",AVERAGEIFS(Productos!$M$2:$M$148,Productos!$B$2:$B$148,A5)) -> 126301.67
A6: AL WATANIAH | B6: Tradición floral del Golfo, expresada con una delicadeza atemporal. | C6: =COUNTIF(Productos!$B$2:$B$148,A6) -> 1 | D6: =COUNTIFS(Productos!$B$2:$B$148,A6,Productos!$M$2:$M$148,"<>") -> 1 | E6: =IF(D6=0,"Consultar",_xlfn.MINIFS(Productos!$M$2:$M$148,Productos!$B$2:$B$148,A6)) -> 45696 | F6: =IF(D6=0,"Consultar",_xlfn.MAXIFS(Productos!$M$2:$M$148,Productos!$B$2:$B$148,A6)) -> 45696 | G6: =IF(D6=0,"Consultar",AVERAGEIFS(Productos!$M$2:$M$148,Productos!$B$2:$B$148,A6)) -> 45696
A7: ARMAF | B7: El poder de una noche inolvidable, embotellado: cítricos vibrantes y una estela imposible de ignorar. | C7: =COUNTIF(Productos!$B$2:$B$148,A7) -> 18 | D7: =COUNTIFS(Productos!$B$2:$B$148,A7,Productos!$M$2:$M$148,"<>") -> 18 | E7: =IF(D7=0,"Consultar",_xlfn.MINIFS(Productos!$M$2:$M$148,Productos!$B$2:$B$148,A7)) -> 56120 | F7: =IF(D7=0,"Consultar",_xlfn.MAXIFS(Productos!$M$2:$M$148,Productos!$B$2:$B$148,A7)) -> 139785 | G7: =IF(D7=0,"Consultar",AVERAGEIFS(Productos!$M$2:$M$148,Productos!$B$2:$B$148,A7)) -> 87766.889
A8: ASDAAF | C8: =COUNTIF(Productos!$B$2:$B$148,A8) -> 2 | D8: =COUNTIFS(Productos!$B$2:$B$148,A8,Productos!$M$2:$M$148,"<>") -> 2 | E8: =IF(D8=0,"Consultar",_xlfn.MINIFS(Productos!$M$2:$M$148,Productos!$B$2:$B$148,A8)) -> 47938 | F8: =IF(D8=0,"Consultar",_xlfn.MAXIFS(Productos!$M$2:$M$148,Productos!$B$2:$B$148,A8)) -> 52995 | G8: =IF(D8=0,"Consultar",AVERAGEIFS(Productos!$M$2:$M$148,Productos!$B$2:$B$148,A8)) -> 50466.5
A9: BHARARA | C9: =COUNTIF(Productos!$B$2:$B$148,A9) -> 2 | D9: =COUNTIFS(Productos!$B$2:$B$148,A9,Productos!$M$2:$M$148,"<>") -> 2 | E9: =IF(D9=0,"Consultar",_xlfn.MINIFS(Productos!$M$2:$M$148,Productos!$B$2:$B$148,A9)) -> 142695 | F9: =IF(D9=0,"Consultar",_xlfn.MAXIFS(Productos!$M$2:$M$148,Productos!$B$2:$B$148,A9)) -> 180258 | G9: =IF(D9=0,"Consultar",AVERAGEIFS(Productos!$M$2:$M$148,Productos!$B$2:$B$148,A9)) -> 161476.5
A10: EMPER | B10: Maderas y cuero de carácter clásico, para quien no necesita levantar la voz. | C10: =COUNTIF(Productos!$B$2:$B$148,A10) -> 2 | D10: =COUNTIFS(Productos!$B$2:$B$148,A10,Productos!$M$2:$M$148,"<>") -> 2 | E10: =IF(D10=0,"Consultar",_xlfn.MINIFS(Productos!$M$2:$M$148,Productos!$B$2:$B$148,A10)) -> 52208 | F10: =IF(D10=0,"Consultar",_xlfn.MAXIFS(Productos!$M$2:$M$148,Productos!$B$2:$B$148,A10)) -> 59577 | G10: =IF(D10=0,"Consultar",AVERAGEIFS(Productos!$M$2:$M$148,Productos!$B$2:$B$148,A10)) -> 55892.5
A11: FRAGRANCE WORLD | B11: Gourmands golosos: el placer convertido en fragancia. | C11: =COUNTIF(Productos!$B$2:$B$148,A11) -> 1 | D11: =COUNTIFS(Productos!$B$2:$B$148,A11,Productos!$M$2:$M$148,"<>") -> 0 | E11: =IF(D11=0,"Consultar",_xlfn.MINIFS(Productos!$M$2:$M$148,Productos!$B$2:$B$148,A11)) -> Consultar | F11: =IF(D11=0,"Consultar",_xlfn.MAXIFS(Productos!$M$2:$M$148,Productos!$B$2:$B$148,A11)) -> Consultar | G11: =IF(D11=0,"Consultar",AVERAGEIFS(Productos!$M$2:$M$148,Productos!$B$2:$B$148,A11)) -> Consultar
A12: FRENCH AVENUE | B12: El romance parisino, reinterpretado en clave oriental. | C12: =COUNTIF(Productos!$B$2:$B$148,A12) -> 7 | D12: =COUNTIFS(Productos!$B$2:$B$148,A12,Productos!$M$2:$M$148,"<>") -> 7 | E12: =IF(D12=0,"Consultar",_xlfn.MINIFS(Productos!$M$2:$M$148,Productos!$B$2:$B$148,A12)) -> 62010 | F12: =IF(D12=0,"Consultar",_xlfn.MAXIFS(Productos!$M$2:$M$148,Productos!$B$2:$B$148,A12)) -> 145318 | G12: =IF(D12=0,"Consultar",AVERAGEIFS(Productos!$M$2:$M$148,Productos!$B$2:$B$148,A12)) -> 105621.71
A13: LATTAFA | B13: La casa más prolífica de la alta perfumería árabe — un universo dentro del catálogo. | C13: =COUNTIF(Productos!$B$2:$B$148,A13) -> 63 | D13: =COUNTIFS(Productos!$B$2:$B$148,A13,Productos!$M$2:$M$148,"<>") -> 55 | E13: =IF(D13=0,"Consultar",_xlfn.MINIFS(Productos!$M$2:$M$148,Productos!$B$2:$B$148,A13)) -> 36418 | F13: =IF(D13=0,"Consultar",_xlfn.MAXIFS(Productos!$M$2:$M$148,Productos!$B$2:$B$148,A13)) -> 159747 | G13: =IF(D13=0,"Consultar",AVERAGEIFS(Productos!$M$2:$M$148,Productos!$B$2:$B$148,A13)) -> 68569.273
A14: MAISON ALHAMBRA | B14: Elegancia europea de inspiración francesa, pulida hasta el último detalle. | C14: =COUNTIF(Productos!$B$2:$B$148,A14) -> 24 | D14: =COUNTIFS(Productos!$B$2:$B$148,A14,Productos!$M$2:$M$148,"<>") -> 21 | E14: =IF(D14=0,"Consultar",_xlfn.MINIFS(Productos!$M$2:$M$148,Productos!$B$2:$B$148,A14)) -> 34344 | F14: =IF(D14=0,"Consultar",_xlfn.MAXIFS(Productos!$M$2:$M$148,Productos!$B$2:$B$148,A14)) -> 80446 | G14: =IF(D14=0,"Consultar",AVERAGEIFS(Productos!$M$2:$M$148,Productos!$B$2:$B$148,A14)) -> 52335.952
A15: OTROS PRODUCTOS Y ACCESORIOS | B15: Complementos y presentaciones especiales para completar la experiencia Altiva. | C15: =COUNTIF(Productos!$B$2:$B$148,A15) -> 2 | D15: =COUNTIFS(Productos!$B$2:$B$148,A15,Productos!$M$2:$M$148,"<>") -> 2 | E15: =IF(D15=0,"Consultar",_xlfn.MINIFS(Productos!$M$2:$M$148,Productos!$B$2:$B$148,A15)) -> 15861 | F15: =IF(D15=0,"Consultar",_xlfn.MAXIFS(Productos!$M$2:$M$148,Productos!$B$2:$B$148,A15)) -> 26926 | G15: =IF(D15=0,"Consultar",AVERAGEIFS(Productos!$M$2:$M$148,Productos!$B$2:$B$148,A15)) -> 21393.5
A16: RASASI | B16: Herencia emiratí convertida en ícono: la saga Hawas y su magnetismo marino. | C16: =COUNTIF(Productos!$B$2:$B$148,A16) -> 8 | D16: =COUNTIFS(Productos!$B$2:$B$148,A16,Productos!$M$2:$M$148,"<>") -> 8 | E16: =IF(D16=0,"Consultar",_xlfn.MINIFS(Productos!$M$2:$M$148,Productos!$B$2:$B$148,A16)) -> 66994 | F16: =IF(D16=0,"Consultar",_xlfn.MAXIFS(Productos!$M$2:$M$148,Productos!$B$2:$B$148,A16)) -> 102936 | G16: =IF(D16=0,"Consultar",AVERAGEIFS(Productos!$M$2:$M$148,Productos!$B$2:$B$148,A16)) -> 90543.625
A17: RAVE | C17: =COUNTIF(Productos!$B$2:$B$148,A17) -> 1 | D17: =COUNTIFS(Productos!$B$2:$B$148,A17,Productos!$M$2:$M$148,"<>") -> 1 | E17: =IF(D17=0,"Consultar",_xlfn.MINIFS(Productos!$M$2:$M$148,Productos!$B$2:$B$148,A17)) -> 54807 | F17: =IF(D17=0,"Consultar",_xlfn.MAXIFS(Productos!$M$2:$M$148,Productos!$B$2:$B$148,A17)) -> 54807 | G17: =IF(D17=0,"Consultar",AVERAGEIFS(Productos!$M$2:$M$148,Productos!$B$2:$B$148,A17)) -> 54807
A18: RAYHAAN | B18: Frescura tropical con alma especiada, para climas y ánimos intensos. | C18: =COUNTIF(Productos!$B$2:$B$148,A18) -> 4 | D18: =COUNTIFS(Productos!$B$2:$B$148,A18,Productos!$M$2:$M$148,"<>") -> 4 | E18: =IF(D18=0,"Consultar",_xlfn.MINIFS(Productos!$M$2:$M$148,Productos!$B$2:$B$148,A18)) -> 88912 | F18: =IF(D18=0,"Consultar",_xlfn.MAXIFS(Productos!$M$2:$M$148,Productos!$B$2:$B$148,A18)) -> 134204 | G18: =IF(D18=0,"Consultar",AVERAGEIFS(Productos!$M$2:$M$148,Productos!$B$2:$B$148,A18)) -> 102375.75
A19: XERJOFF | B19: Alta perfumería italiana de nicho: artesanía, rareza y materias primas excepcionales. | C19: =COUNTIF(Productos!$B$2:$B$148,A19) -> 1 | D19: =COUNTIFS(Productos!$B$2:$B$148,A19,Productos!$M$2:$M$148,"<>") -> 1 | E19: =IF(D19=0,"Consultar",_xlfn.MINIFS(Productos!$M$2:$M$148,Productos!$B$2:$B$148,A19)) -> 410697 | F19: =IF(D19=0,"Consultar",_xlfn.MAXIFS(Productos!$M$2:$M$148,Productos!$B$2:$B$148,A19)) -> 410697 | G19: =IF(D19=0,"Consultar",AVERAGEIFS(Productos!$M$2:$M$148,Productos!$B$2:$B$148,A19)) -> 410697
A20: TOTAL | B20: Suma de todas las casas | C20: =SUM(C4:C19) -> 147 | D20: =SUM(D4:D19) -> 134 | E20: =MIN(Productos!$M$2:$M$148) -> 15861 | F20: =MAX(Productos!$M$2:$M$148) -> 410697 | G20: =AVERAGE(Productos!$M$2:$M$148) -> 78054.179
A22: Control: el total de fragancias coincide con la hoja Productos | C22: =IF(C20=COUNTA(Productos!$C$2:$C$148),"OK","REVISAR") -> OK

Sheet Info
A1: Altiva Essentia · Catálogo de fragancias
A3: Marca | B3: ALTIVA ESSENTIA
A4: Eslogan | B4: Sofisticación, proyección excepcional y esencias imponentes
A5: Teléfono | B5: +54 9 351 652-1368
A6: WhatsApp | B6: https://wa.me/5493516521368
A8: Total de fragancias | B8: =COUNTA(Productos!$C$2:$C$148) -> 147
A9: Casas | B9: =COUNTA(Casas!$A$4:$A$19) -> 16
A10: Con precio publicado | B10: =COUNT(Productos!$M$2:$M$148) -> 134
A11: A consultar | B11: =COUNTA(Productos!$C$2:$C$148)-COUNT(Productos!$M$2:$M$148) -> 13
A12: Destacados | B12: =COUNTIF(Productos!$D$2:$D$148,"Sí") -> 16
A14: Notas de los datos
A15: Fuente | B15: Catálogo HTML publicado (c74c15bb-index.html). Los datos se transcribieron tal cual figuran en la página.
A16: Precio (ARS) | B16: Precio tal como aparece en el catálogo. Celda vacía = precio a consultar (se muestra como 'Consultar' en Precio mostrado).
A17: Presentación | B17: Texto original del catálogo (ej. 'EDP 100ML').
A18: Tipo y Volumen | B18: Derivados de la Presentación: Tipo = concentración o formato (EDP, ELIXIR, EXTRAIT PARFUM, SET, etc.); Volumen = mililitros.
A19: Año y Duración | B19: Texto original del catálogo. 'Consultar' se mantiene así. Los 2 accesorios no tienen estos datos y quedan vacíos.
A20: Notas olfativas | B20: Lista original del catálogo, separadas por coma.
A21: Foto (archivo) | B21: Ruta relativa a la carpeta 'imagenes/' que acompaña este archivo (formato WebP). 15 productos no tienen foto.
A22: Orden | B22: Por casa (A-Z) y luego por producto (A-Z).
A24: Manifiesto
B25: Altiva Essentia nace de una convicción simple: el perfume no se compra, se elige. Cada fragancia de este catálogo fue reunida pensando en quien entiende que un aroma es la primera impresión que se deja y la última que se recuerda — poder y delicadeza en el mismo gesto.
B26: Reunimos, casa por casa, las firmas más codiciadas de la alta perfumería árabe y europea: ámbares intensos, oud especiado, gourmands imposibles de olvidar y flores que perduran mucho después de la piel. Altiva Essentia no es solo un nombre — es una promesa de sofisticación, hecha esencia.
